Workbook
Name Estimation_Engineer: [1]Misc!$F$4:$F$6
Name LIFECO227ea_Actuation: '[2]Lifeco-227ea Cylinder Range'!$C$3:$O$13
Name LIFECO227ea_CylindersList: '[2]Lifeco-227ea Cylinder Range'!$C$3:$C$13
Name LIFECO227ea_CylindersPrice: '[2]Lifeco-227ea Cylinder Range'!$C$3:$G$13
Name LIFECO5112_Actuation: '[2]Lifeco-5112 Cylinder Range'!$C$3:$O$16
Name LIFECO5112_CylindersList: '[2]Lifeco-5112 Cylinder Range'!$C$3:$C$16
Name LIFECO5112_CylindersPrice: '[2]Lifeco-5112 Cylinder Range'!$C$3:$G$16
Name ProductList: [3]PRICELIST!$C$3:$C$1119
Name Sales_Person: [1]Misc!$B$4:$B$10
Name Sales_Person_Details: [1]Misc!$A$4:$D$21

Sheet UL Electric VTP 50Hz 30VT
A1: UL Electric VTP 50Hz 30VT
A2: Item of | B2: SFFECO Item Code | C2: Electric Panel Item Code | D2: Description | F2: LIFECO-UK GP (USD) | H2: LIFECO-UK GP (AED)
A3: LIFECO-UK | B3: 126064200880 | C3: 088001200067 | D3: LIFECO-UK-UL Listed Vertical Turbine Pump (LFP 200-30 VT-2900RPM) 200 GPM @ 6 Bar, Coupled with 50Hz VHS Motor. Pressure Gauge, Air Release Valve and Casing Relief Valve are included. | F3: 19675.234 | H3: 72306.484
A4: LIFECO-UK | B4: 126064200881 | C4: 088001200067 | D4: LIFECO-UK-UL Listed Vertical Turbine Pump (LFP 200-30 VT-2900RPM) 200 GPM @ 7 Bar, Coupled with 50Hz VHS Motor. Pressure Gauge, Air Release Valve and Casing Relief Valve are included. | F4: 19675.234 | H4: 72306.484
A5: LIFECO-UK | B5: 126064200882 | C5: 088001200080 | D5: LIFECO-UK-UL Listed Vertical Turbine Pump (LFP 200-30 VT-2900RPM) 200 GPM @ 8 Bar, Coupled with 50Hz VHS Motor. Pressure Gauge, Air Release Valve and Casing Relief Valve are included. | F5: 21638.941 | H5: 79523.109
A6: LIFECO-UK | B6: 126064200883 | C6: 088001200079 | D6: LIFECO-UK-UL Listed Vertical Turbine Pump (LFP 200-30 VT-2900RPM) 200 GPM @ 9 to 11 Bar, Coupled with 50Hz VHS Motor. Pressure Gauge, Air Release Valve and Casing Relief Valve are included. | F6: 23254.63 | H6: 85460.767
A7: LIFECO-UK | B7: 126064200884 | C7: 088001200068 | D7: LIFECO-UK-UL Listed Vertical Turbine Pump (LFP 200-30 VT-2900RPM) 200 GPM @ 12 to 14 Bar, Coupled with 50Hz VHS Motor. Pressure Gauge, Air Release Valve and Casing Relief Valve are included. | F7: 24729.891 | H7: 90882.351
A8: LIFECO-UK | B8: 126064200400 | C8: 088001200070 | D8: LIFECO-UK-UL Listed Vertical Turbine Pump (LFP 200-30 VT-2900RPM) 200 GPM @ 15 Bar, Coupled with 50Hz ODP Electric Motor and Gear Drive. Pressure Gauge, Air Release Valve and Casing Relief Valve are included. | F8: 29770.048 | H8: 109404.93
A9: LIFECO-UK | B9: 126064200401 | C9: 088001200070 | D9: LIFECO-UK-UL Listed Vertical Turbine Pump (LFP 200-30 VT-2900RPM) 200 GPM @ 16 Bar, Coupled with 50Hz ODP Electric Motor and Gear Drive. Pressure Gauge, Air Release Valve and Casing Relief Valve are included. | F9: 30761.442 | H9: 113048.3
A10: LIFECO-UK | B10: 126064200402 | C10: 088001200070 | D10: LIFECO-UK-UL Listed Vertical Turbine Pump (LFP 200-30 VT-2900RPM) 200 GPM @ 17 Bar, Coupled with 50Hz ODP Electric Motor and Gear Drive. Pressure Gauge, Air Release Valve and Casing Relief Valve are included. | F10: 30761.442 | H10: 113048.3
A11: LIFECO-UK | B11: 126064200403 | C11: 088001200070 | D11: LIFECO-UK-UL Listed Vertical Turbine Pump (LFP 200-30 VT-2900RPM) 200 GPM @ 18 Bar, Coupled with 50Hz ODP Electric Motor and Gear Drive. Pressure Gauge, Air Release Valve and Casing Relief Valve are included. | F11: 30761.442 | H11: 113048.3
A12: LIFECO-UK | B12: 126064200404 | C12: 088001200038 | D12: LIFECO-UK-UL Listed Vertical Turbine Pump (LFP 200-30 VT-2980RPM) 200 GPM @ 19 Bar, Coupled with 50Hz ODP Electric Motor and Gear Drive. Pressure Gauge, Air Release Valve and Casing Relief Valve are included. | F12: 33723.412 | H12: 123933.54
A13: LIFECO-UK | B13: 126064200405 | C13: 088001200038 | D13: LIFECO-UK-UL Listed Vertical Turbine Pump (LFP 200-30 VT-2900RPM) 200 GPM @ 20 Bar, Coupled with 50Hz ODP Electric Motor and Gear Drive. Pressure Gauge, Air Release Valve and Casing Relief Valve are included. | F13: 35311.626 | H13: 129770.23
A14: LIFECO-UK | B14: 126064200885 | C14: 088001200067 | D14: LIFECO-UK-UL Listed Vertical Turbine Pump (LFP 250-30 VT-2900RPM) 250 GPM @ 6 Bar, Coupled with 50Hz VHS Motor. Pressure Gauge, Air Release Valve and Casing Relief Valve are included. | F14: 19675.234 | H14: 72306.484
A15: LIFECO-UK | B15: 126064200886 | C15: 088001200080 | D15: LIFECO-UK-UL Listed Vertical Turbine Pump (LFP 250-30 VT-2900RPM) 250 GPM @ 7 Bar, Coupled with 50Hz VHS Motor. Pressure Gauge, Air Release Valve and Casing Relief Valve are included. | F15: 20346.848 | H15: 74774.665
A16: LIFECO-UK | B16: 126064200887 | C16: 088001200080 | D16: LIFECO-UK-UL Listed Vertical Turbine Pump (LFP 250-30 VT-2900RPM) 250 GPM @ 8 Bar, Coupled with 50Hz VHS Motor. Pressure Gauge, Air Release Valve and Casing Relief Valve are included. | F16: 21638.941 | H16: 79523.109
A17: LIFECO-UK | B17: 126064200888 | C17: 088001200079 | D17: LIFECO-UK-UL Listed Vertical Turbine Pump (LFP 250-30 VT-2900RPM) 250 GPM @ 9 to 10 Bar, Coupled with 50Hz VHS Motor. Pressure Gauge, Air Release Valve and Casing Relief Valve are included. | F17: 23254.63 | H17: 85460.767
A18: LIFECO-UK | B18: 126064200889 | C18: 088001200068 | D18: LIFECO-UK-UL Listed Vertical Turbine Pump (LFP 250-30 VT-2900RPM) 250 GPM @ 11 to 14 Bar, Coupled with 50Hz VHS Motor. Pressure Gauge, Air Release Valve and Casing Relief Valve are included. | F18: 24729.891 | H18: 90882.351
A19: LIFECO-UK | B19: 126064200412 | C19: 088001200070 | D19: LIFECO-UK-UL Listed Vertical Turbine Pump (LFP 250-30 VT-2980RPM) 250 GPM @ 15 Bar, Coupled with 50Hz ODP Electric Motor and Gear Drive. Pressure Gauge, Air Release Valve and Casing Relief Valve are included. | F19: 29770.048 | H19: 109404.93
A20: LIFECO-UK | B20: 126064200413 | C20: 088001200070 | D20: LIFECO-UK-UL Listed Vertical Turbine Pump (LFP 250-30 VT-2900RPM) 250 GPM @ 16 Bar, Coupled with 50Hz ODP Electric Motor and Gear Drive. Pressure Gauge, Air Release Valve and Casing Relief Valve are included. | F20: 30761.442 | H20: 113048.3
A21: LIFECO-UK | B21: 126064200414 | C21: 088001200070 | D21: LIFECO-UK-UL Listed Vertical Turbine Pump (LFP 250-30 VT-2900RPM) 250 GPM @ 17 Bar, Coupled with 50Hz ODP Electric Motor and Gear Drive. Pressure Gauge, Air Release Valve and Casing Relief Valve are included. | F21: 30761.442 | H21: 113048.3
A22: LIFECO-UK | B22: 126064200415 | C22: 088001200038 | D22: LIFECO-UK-UL Listed Vertical Turbine Pump (LFP 250-30 VT-2900RPM) 250 GPM @ 18 Bar, Coupled with 50Hz ODP Electric Motor and Gear Drive. Pressure Gauge, Air Release Valve and Casing Relief Valve are included. | F22: 33723.412 | H22: 123933.54
A23: LIFECO-UK | B23: 126064200416 | C23: 088001200038 | D23: LIFECO-UK-UL Listed Vertical Turbine Pump (LFP 250-30 VT-2900RPM) 250 GPM @ 19 to 20 Bar, Coupled with 50Hz ODP Electric Motor and Gear Drive. Pressure Gauge, Air Release Valve and Casing Relief Valve are included. | F23: 35311.626 | H23: 129770.23
A24: LIFECO-UK | B24: 126064200890 | C24: 088001200067 | D24: LIFECO-UK-UL Listed Vertical Turbine Pump (LFP 300-30 VT-2900RPM) 300 GPM @ 6 Bar, Coupled with 50Hz VHS Motor. Pressure Gauge, Air Release Valve and Casing Relief Valve are included. | F24: 19675.234 | H24: 72306.484
A25: LIFECO-UK | B25: 126064200891 | C25: 088001200080 | D25: LIFECO-UK-UL Listed Vertical Turbine Pump (LFP 300-30 VT-2900RPM) 300 GPM @ 7 Bar, Coupled with 50Hz VHS Motor. Pressure Gauge, Air Release Valve and Casing Relief Valve are included. | F25: 20346.848 | H25: 74774.665
A26: LIFECO-UK | B26: 126064200892 | C26: 088001200080 | D26: LIFECO-UK-UL Listed Vertical Turbine Pump (LFP 300-30 VT-2900RPM) 300 GPM @ 8 Bar, Coupled with 50Hz VHS Motor. Pressure Gauge, Air Release Valve and Casing Relief Valve are included. | F26: 21638.941 | H26: 79523.109
A27: LIFECO-UK | B27: 126064200893 | C27: 088001200079 | D27: LIFECO-UK-UL Listed Vertical Turbine Pump (LFP 300-30 VT-2900RPM) 300 GPM @ 9 to 10 Bar, Coupled with 50Hz VHS Motor. Pressure Gauge, Air Release Valve and Casing Relief Valve are included. | F27: 23254.63 | H27: 85460.767
A28: LIFECO-UK | B28: 126064200894 | C28: 088001200068 | D28: LIFECO-UK-UL Listed Vertical Turbine Pump (LFP 300-30 VT-2900RPM) 300 GPM @ 11 to 13 Bar, Coupled with 50Hz VHS Motor. Pressure Gauge, Air Release Valve and Casing Relief Valve are included. | F28: 24729.891 | H28: 90882.351
A29: LIFECO-UK | B29: 126064200422 | C29: 088001200070 | D29: LIFECO-UK-UL Listed Vertical Turbine Pump (LFP 300-30 VT-2900RPM) 300 GPM @ 14 Bar, Coupled with 50Hz ODP Electric Motor and Gear Drive. Pressure Gauge, Air Release Valve and Casing Relief Valve are included. | F29: 29770.048 | H29: 109404.93
A30: LIFECO-UK | B30: 126064200423 | C30: 088001200070 | D30: LIFECO-UK-UL Listed Vertical Turbine Pump (LFP 300-30 VT-2900RPM) 300 GPM @ 15 Bar, Coupled with 50Hz ODP Electric Motor and Gear Drive. Pressure Gauge, Air Release Valve and Casing Relief Valve are included. | F30: 30761.442 | H30: 113048.3
A31: LIFECO-UK | B31: 126064200424 | C31: 088001200070 | D31: LIFECO-UK-UL Listed Vertical Turbine Pump (LFP 300-30 VT-2900RPM) 300 GPM @ 16 to 17 Bar, Coupled with 50Hz ODP Electric Motor and Gear Drive. Pressure Gauge, Air Release Valve and Casing Relief Valve are included. | F31: 30761.442 | H31: 113048.3
A32: LIFECO-UK | B32: 126064200425 | C32: 088001200038 | D32: LIFECO-UK-UL Listed Vertical Turbine Pump (LFP 300-30 VT-2900RPM) 300 GPM @ 18 Bar, Coupled with 50Hz ODP Electric Motor and Gear Drive. Pressure Gauge, Air Release Valve and Casing Relief Valve are included. | F32: 33723.412 | H32: 123933.54
A33: LIFECO-UK | B33: 126064200426 | C33: 088001200038 | D33: LIFECO-UK-UL Listed Vertical Turbine Pump (LFP 300-30 VT-2900RPM) 300 GPM @ 19 Bar, Coupled with 50Hz ODP Electric Motor and Gear Drive. Pressure Gauge, Air Release Valve and Casing Relief Valve are included. | F33: 35311.626 | H33: 129770.23
A34: LIFECO-UK | B34: 126064200427 | C34: 088001200038 | D34: LIFECO-UK-UL Listed Vertical Turbine Pump (LFP 300-30 VT-2900RPM) 300 GPM @ 20 Bar, Coupled with 50Hz ODP Electric Motor and Gear Drive. Pressure Gauge, Air Release Valve and Casing Relief Valve are included. | F34: 35311.626 | H34: 129770.23
A35: LIFECO-UK | B35: 126064200895 | C35: 088001200067 | D35: LIFECO-UK-UL Listed Vertical Turbine Pump (LFP 400-30 VT-2900RPM) 400 GPM @ 6 Bar, Coupled with 50Hz VHS Motor. Pressure Gauge, Air Release Valve and Casing Relief Valve are included. | F35: 19675.234 | H35: 72306.484
A36: LIFECO-UK | B36: 126064200896 | C36: 088001200080 | D36: LIFECO-UK-UL Listed Vertical Turbine Pump (LFP 400-30 VT-2900RPM) 400 GPM @ 7 to 8 Bar, Coupled with 50Hz VHS Motor. Pressure Gauge, Air Release Valve and Casing Relief Valve are included. | F36: 21638.941 | H36: 79523.109
A37: LIFECO-UK | B37: 126064200897 | C37: 088001200079 | D37: LIFECO-UK-UL Listed Vertical Turbine Pump (LFP 400-30 VT-2900RPM) 400 GPM @ 9 Bar, Coupled with 50Hz VHS Motor. Pressure Gauge, Air Release Valve and Casing Relief Valve are included. | F37: 23254.63 | H37: 85460.767
A38: LIFECO-UK | B38: 126064200898 | C38: 088001200068 | D38: LIFECO-UK-UL Listed Vertical Turbine Pump (LFP 400-30 VT-2900RPM) 400 GPM @ 10 Bar, Coupled with 50Hz VHS Motor. Pressure Gauge, Air Release Valve and Casing Relief Valve are included. | F38: 23557.62 | H38: 86574.253
A39: LIFECO-UK | B39: 126064200899 | C39: 088001200068 | D39: LIFECO-UK-UL Listed Vertical Turbine Pump (LFP 400-30 VT-2900RPM) 400 GPM @ 11 to 13 Bar, Coupled with 50Hz VHS Motor. Pressure Gauge, Air Release Valve and Casing Relief Valve are included. | F39: 24729.891 | H39: 90882.351
A40: LIFECO-UK | B40: 126064200433 | C40: 088001200070 | D40: LIFECO-UK-UL Listed Vertical Turbine Pump (LFP 400-30 VT-2980RPM) 400 GPM @ 14 Bar, Coupled with 50Hz ODP Electric Motor and Gear Drive. Pressure Gauge, Air Release Valve and Casing Relief Valve are included. | F40: 29770.048 | H40: 109404.93
...

Sheet UL Diesel VTP 30VT
A1: UL Diesel VTP 30VT
A2: Item of | B2: Item Code | C2: Control Panel Item Code | D2: Standard Diesel Tank Item Code | E2: Description | G2: LIFECO-UK GP (USD) | I2: LIFECO-UK GP (AED)
A3: LIFECO-UK | B3: 126064200475 | C3: 088001200060 | D3: 074003200263 | E3: LIFECO-UK-UL Listed Vertical Turbine Pump (LFP 200-30 VT-2900RPM) 200 GPM @ 6 Bar, Coupled with Diesel Engine and Gear Drive. Pressure Gauge & Air Release Valve are included. | G3: =I3/3.675 -> 30207.36 | I3: 111012.05
A4: LIFECO-UK | B4: 126064200476 | C4: 088001200060 | D4: 074003200263 | E4: LIFECO-UK-UL Listed Vertical Turbine Pump (LFP 200-30 VT-2900RPM) 200 GPM @ 7 Bar, Coupled with Diesel Engine and Gear Drive. Pressure Gauge & Air Release Valve are included. | G4: =I4/3.675 -> 30207.36 | I4: 111012.05
A5: LIFECO-UK | B5: 126064200477 | C5: 088001200060 | D5: 074003200263 | E5: LIFECO-UK-UL Listed Vertical Turbine Pump (LFP 200-30 VT-3000RPM) 200 GPM @ 8 Bar, Coupled with Diesel Engine and Gear Drive. Pressure Gauge & Air Release Valve are included. | G5: =I5/3.675 -> 30283.68 | I5: 111292.52
A6: LIFECO-UK | B6: 126064200478 | C6: 088001200060 | D6: 074003200263 | E6: LIFECO-UK-UL Listed Vertical Turbine Pump (LFP 200-30 VT-2900RPM) 200 GPM @ 9 to 10 Bar, Coupled with Diesel Engine and Gear Drive. Pressure Gauge & Air Release Valve are included. | G6: =I6/3.675 -> 33316.627 | I6: 122438.61
A7: LIFECO-UK | B7: 126064200479 | C7: 088001200063 | D7: 074003200263 | E7: LIFECO-UK-UL Listed Vertical Turbine Pump (LFP 200-30 VT-2900RPM) 200 GPM @ 11 Bar, Coupled with Diesel Engine and Gear Drive. Pressure Gauge & Air Release Valve are included. | G7: =I7/3.675 -> 35320.784 | I7: 129803.88
A8: LIFECO-UK | B8: 126064200916 | C8: 088001200063 | D8: 074003200315 | E8: LIFECO-UK-UL Listed Vertical Turbine Pump (LFP 200-30 VT-3000RPM) 200 GPM @ 12 Bar, Coupled with Diesel Engine and Gear Drive. Pressure Gauge & Air Release Valve are included. | G8: =I8/3.675 -> 36133.59 | I8: 132790.94
A9: LIFECO-UK | B9: 126064200480 | C9: 088001200063 | D9: 074003200315 | E9: LIFECO-UK-UL Listed Vertical Turbine Pump (LFP 200-30 VT-2900RPM) 200 GPM @ 13 to 14 Bar, Coupled with Diesel Engine and Gear Drive. Pressure Gauge & Air Release Valve are included. | G9: =I9/3.675 -> 37271.517 | I9: 136972.83
A10: LIFECO-UK | B10: 126064200481 | C10: 088001200063 | D10: 074003200315 | E10: LIFECO-UK-UL Listed Vertical Turbine Pump (LFP 200-30 VT-2900RPM) 200 GPM @ 15 Bar, Coupled with Diesel Engine and Gear Drive. Pressure Gauge & Air Release Valve are included. | G10: =I10/3.675 -> 37293.65 | I10: 137054.16
A11: LIFECO-UK | B11: 126064200482 | C11: 088001200063 | D11: 074003200315 | E11: LIFECO-UK-UL Listed Vertical Turbine Pump (LFP 200-30 VT-3000RPM) 200 GPM @ 16 Bar, Coupled with FM approved Diesel Engine and Gear Drive. Pressure Gauge & Air Release Valve are included. | G11: =I11/3.675 -> 39964.842 | I11: 146870.79
A12: LIFECO-UK | B12: 126064200483 | C12: 088001200063 | D12: 074003200315 | E12: LIFECO-UK-UL Listed Vertical Turbine Pump (LFP 200-30 VT-2900RPM) 200 GPM @ 17 Bar, Coupled with FM approved Diesel Engine and Gear Drive. Pressure Gauge & Air Release Valve are included. | G12: =I12/3.675 -> 40851.677 | I12: 150129.91
A13: LIFECO-UK | B13: 126064200484 | C13: 088001200063 | D13: 074003200315 | E13: LIFECO-UK-UL Listed Vertical Turbine Pump (LFP 200-30 VT-2900RPM) 200 GPM @ 18 Bar, Coupled with FM approved Diesel Engine and Gear Drive. Pressure Gauge & Air Release Valve are included. | G13: =I13/3.675 -> 40851.677 | I13: 150129.91
A14: LIFECO-UK | B14: 126064200485 | C14: 088001200063 | D14: 074003200314 | E14: LIFECO-UK-UL Listed Vertical Turbine Pump (LFP 200-30 VT-2980RPM) 200 GPM @ 19 Bar, Coupled with FM approved Diesel Engine and Gear Drive. Pressure Gauge & Air Release Valve are included. | G14: =I14/3.675 -> 43948.733 | I14: 161511.59
A15: LIFECO-UK | B15: 126064200486 | C15: 088001200063 | D15: 074003200314 | E15: LIFECO-UK-UL Listed Vertical Turbine Pump (LFP 200-30 VT-2900RPM) 200 GPM @ 20 Bar, Coupled with Diesel Engine and Gear Drive. Pressure Gauge & Air Release Valve are included. | G15: =I15/3.675 -> 45536.947 | I15: 167348.28
A16: LIFECO-UK | B16: 126064200487 | C16: 088001200060 | D16: 074003200263 | E16: LIFECO-UK-UL Listed Vertical Turbine Pump (LFP 250-30 VT-2900RPM) 250 GPM @ 6 Bar, Coupled with Diesel Engine and Gear Drive. Pressure Gauge & Air Release Valve are included. | G16: =I16/3.675 -> 30207.36 | I16: 111012.05
A17: LIFECO-UK | B17: 126064200488 | C17: 088001200060 | D17: 074003200263 | E17: LIFECO-UK-UL Listed Vertical Turbine Pump (LFP 250-30 VT-2900RPM) 250 GPM @ 7 Bar, Coupled with Diesel Engine and Gear Drive. Pressure Gauge & Air Release Valve are included. | G17: =I17/3.675 -> 30207.36 | I17: 111012.05
A18: LIFECO-UK | B18: 126064200489 | C18: 088001200060 | D18: 074003200263 | E18: LIFECO-UK-UL Listed Vertical Turbine Pump (LFP 250-30 VT-2900RPM) 250 GPM @ 8 Bar, Coupled with Diesel Engine and Gear Drive. Pressure Gauge & Air Release Valve are included. | G18: =I18/3.675 -> 32193.964 | I18: 118312.82
A19: LIFECO-UK | B19: 126064200490 | C19: 088001200060 | D19: 074003200263 | E19: LIFECO-UK-UL Listed Vertical Turbine Pump (LFP 250-30 VT-2900RPM) 250 GPM @ 9 Bar, Coupled with Diesel Engine and Gear Drive. Pressure Gauge & Air Release Valve are included. | G19: =I19/3.675 -> 33316.627 | I19: 122438.61
A20: LIFECO-UK | B20: 126064200491 | C20: 088001200060 | D20: 074003200263 | E20: LIFECO-UK-UL Listed Vertical Turbine Pump (LFP 250-30 VT-2900RPM) 250 GPM @ 10 Bar, Coupled with Diesel Engine and Gear Drive. Pressure Gauge & Air Release Valve are included. | G20: =I20/3.675 -> 33316.627 | I20: 122438.61
A21: LIFECO-UK | B21: 126064200917 | C21: 088001200063 | D21: 074003200315 | E21: LIFECO-UK-UL Listed Vertical Turbine Pump (LFP 250-30 VT-3000RPM) 250 GPM @ 11 Bar, Coupled with Diesel Engine and Gear Drive. Pressure Gauge & Air Release Valve are included. | G21: =I21/3.675 -> 36133.59 | I21: 132790.94
A22: LIFECO-UK | B22: 126064200492 | C22: 088001200063 | D22: 074003200315 | E22: LIFECO-UK-UL Listed Vertical Turbine Pump (LFP 250-30 VT-2900RPM) 250 GPM @ 12 to 14 Bar, Coupled with Diesel Engine and Gear Drive. Pressure Gauge & Air Release Valve are included. | G22: =I22/3.675 -> 37271.517 | I22: 136972.83
A23: LIFECO-UK | B23: 126064200493 | C23: 088001200063 | D23: 074003200315 | E23: LIFECO-UK-UL Listed Vertical Turbine Pump (LFP 250-30 VT-3000RPM) 250 GPM @ 15 Bar, Coupled with Diesel Engine and Gear Drive. Pressure Gauge & Air Release Valve are included. | G23: =I23/3.675 -> 39964.842 | I23: 146870.79
A24: LIFECO-UK | B24: 126064200494 | C24: 088001200063 | D24: 074003200315 | E24: LIFECO-UK-UL Listed Vertical Turbine Pump (LFP 250-30 VT-2900RPM) 250 GPM @ 16 Bar, Coupled with FM approved Diesel Engine and Gear Drive. Pressure Gauge & Air Release Valve are included. | G24: =I24/3.675 -> 40775.357 | I24: 149849.44
A25: LIFECO-UK | B25: 126064200495 | C25: 088001200063 | D25: 074003200315 | E25: LIFECO-UK-UL Listed Vertical Turbine Pump (LFP 250-30 VT-2900RPM) 250 GPM @ 17 Bar, Coupled with FM approved Diesel Engine and Gear Drive. Pressure Gauge & Air Release Valve are included. | G25: =I25/3.675 -> 40851.677 | I25: 150129.91
A26: LIFECO-UK | B26: 126064200496 | C26: 088001200063 | D26: 074003200314 | E26: LIFECO-UK-UL Listed Vertical Turbine Pump (LFP 250-30 VT-2900RPM) 250 GPM @ 18 Bar, Coupled with FM approved Diesel Engine and Gear Drive. Pressure Gauge & Air Release Valve are included. | G26: =I26/3.675 -> 43948.733 | I26: 161511.59
A27: LIFECO-UK | B27: 126064200497 | C27: 088001200063 | D27: 074003200314 | E27: LIFECO-UK-UL Listed Vertical Turbine Pump (LFP 250-30 VT-3000RPM) 250 GPM @ 19 Bar, Coupled with Diesel Engine and Gear Drive. Pressure Gauge & Air Release Valve are included. | G27: =I27/3.675 -> 43948.733 | I27: 161511.59
A28: LIFECO-UK | B28: 126064200918 | C28: 088001200063 | D28: 074003200314 | E28: LIFECO-UK-UL Listed Vertical Turbine Pump (LFP 250-30 VT-2900RPM) 250 GPM @ 20 Bar, Coupled with Diesel Engine and Gear Drive. Pressure Gauge & Air Release Valve are included. | G28: =I28/3.675 -> 45536.947 | I28: 167348.28
A29: LIFECO-UK | B29: 126064200498 | C29: 088001200060 | D29: 074003200263 | E29: LIFECO-UK-UL Listed Vertical Turbine Pump (LFP 300-30 VT-2900RPM) 300 GPM @ 6 Bar, Coupled with Diesel Engine and Gear Drive. Pressure Gauge & Air Release Valve are included. | G29: =I29/3.675 -> 30207.36 | I29: 111012.05
A30: LIFECO-UK | B30: 126064200499 | C30: 088001200060 | D30: 074003200263 | E30: LIFECO-UK-UL Listed Vertical Turbine Pump (LFP 300-30 VT-2900RPM) 300 GPM @ 7 Bar, Coupled with Diesel Engine and Gear Drive. Pressure Gauge & Air Release Valve are included. | G30: =I30/3.675 -> 30207.36 | I30: 111012.05
A31: LIFECO-UK | B31: 126064200500 | C31: 088001200060 | D31: 074003200263 | E31: LIFECO-UK-UL Listed Vertical Turbine Pump (LFP 300-30 VT-2900RPM) 300 GPM @ 8 Bar, Coupled with Diesel Engine and Gear Drive. Pressure Gauge & Air Release Valve are included. | G31: =I31/3.675 -> 32270.284 | I31: 118593.29
A32: LIFECO-UK | B32: 126064200501 | C32: 088001200060 | D32: 074003200263 | E32: LIFECO-UK-UL Listed Vertical Turbine Pump (LFP 300-30 VT-2900RPM) 300 GPM @ 9 to 10 Bar, Coupled with Diesel Engine and Gear Drive. Pressure Gauge & Air Release Valve are included. | G32: =I32/3.675 -> 33316.627 | I32: 122438.61
A33: LIFECO-UK | B33: 126064200919 | C33: 088001200063 | D33: 074003200315 | E33: LIFECO-UK-UL Listed Vertical Turbine Pump (LFP 300-30 VT-3000RPM) 300 GPM @ 11 Bar, Coupled with Diesel Engine and Gear Drive. Pressure Gauge & Air Release Valve are included. | G33: =I33/3.675 -> 36133.59 | I33: 132790.94
A34: LIFECO-UK | B34: 126064200502 | C34: 088001200063 | D34: 074003200315 | E34: LIFECO-UK-UL Listed Vertical Turbine Pump (LFP 300-30 VT-2900RPM) 300 GPM @ 12 to 13 Bar, Coupled with Diesel Engine and Gear Drive. Pressure Gauge & Air Release Valve are included. | G34: =I34/3.675 -> 37271.517 | I34: 136972.83
A35: LIFECO-UK | B35: 126064200503 | C35: 088001200063 | D35: 074003200315 | E35: LIFECO-UK-UL Listed Vertical Turbine Pump (LFP 300-30 VT-2900RPM) 300 GPM @ 14 Bar, Coupled with Diesel Engine and Gear Drive. Pressure Gauge & Air Release Valve are included. | G35: =I35/3.675 -> 37293.65 | I35: 137054.16
A36: LIFECO-UK | B36: 126064200504 | C36: 088001200063 | D36: 074003200315 | E36: LIFECO-UK-UL Listed Vertical Turbine Pump (LFP 300-30 VT-3000RPM) 300 GPM @ 15 Bar, Coupled with FM approved Diesel Engine and Gear Drive. Pressure Gauge & Air Release Valve are included. | G36: =I36/3.675 -> 39964.842 | I36: 146870.79
A37: LIFECO-UK | B37: 126064200505 | C37: 088001200063 | D37: 074003200315 | E37: LIFECO-UK-UL Listed Vertical Turbine Pump (LFP 300-30 VT-2900RPM) 300 GPM @ 16 Bar, Coupled with Diesel Engine and Gear Drive. Pressure Gauge & Air Release Valve are included. | G37: =I37/3.675 -> 40775.357 | I37: 149849.44
A38: LIFECO-UK | B38: 126064200506 | C38: 088001200063 | D38: 074003200315 | E38: LIFECO-UK-UL Listed Vertical Turbine Pump (LFP 300-30 VT-2900RPM) 300 GPM @ 17 Bar, Coupled with Diesel Engine and Gear Drive. Pressure Gauge & Air Release Valve are included. | G38: =I38/3.675 -> 41538.555 | I38: 152654.19
A39: LIFECO-UK | B39: 126064200920 | C39: 088001200063 | D39: 074003200314 | E39: LIFECO-UK-UL Listed Vertical Turbine Pump (LFP 300-30 VT-2900RPM) 300 GPM @ 18 Bar, Coupled with FM Approved Diesel Engine and Gear Drive. Pressure Gauge & Air Release Valve are included. | G39: =I39/3.675 -> 43948.733 | I39: 161511.59
A40: LIFECO-UK | B40: 126064200507 | C40: 088001200063 | D40: 074003200314 | E40: LIFECO-UK-UL Listed Vertical Turbine Pump (LFP 300-30 VT-3000RPM) 300 GPM @ 19 Bar, Coupled with Diesel Engine and Gear Drive. Pressure Gauge & Air Release Valve are included. | G40: =I40/3.675 -> 43948.733 | I40: 161511.59
...

Sheet UL Electric VTP 60Hz 30VT
A1: UL Electric VTP 60Hz 30VT
A2: Item of | B2: Item Code | C2: Electric Panel Item Code | D2: Description | F2: LIFECO-UK GP (USD) | H2: LIFECO-UK GP (AED)
A3: LIFECO-UK | B3: 126064200556 | C3: 107002200003 | D3: LIFECO-UK-UL Listed Vertical Turbine Pump (LFP 200-30 VT-2900RPM) 200 GPM @ 6 Bar, Coupled with 60Hz ODP Electric Motor and Gear Drive. Pressure Gauge, Air Release Valve and Casing Relief Valve are included. | F3: =H3/3.675 -> 23779.71 | H3: 87390.436
A4: LIFECO-UK | B4: 126064200557 | C4: 107002200003 | D4: LIFECO-UK-UL Listed Vertical Turbine Pump (LFP 200-30 VT-2900RPM) 200 GPM @ 7 Bar, Coupled with 60Hz ODP Electric Motor and Gear Drive. Pressure Gauge, Air Release Valve and Casing Relief Valve are included. | F4: =H4/3.675 -> 23779.71 | H4: 87390.436
A5: LIFECO-UK | B5: 126064200558 | C5: 088001200095 | D5: LIFECO-UK-UL Listed Vertical Turbine Pump (LFP 200-30 VT-2900RPM) 200 GPM @ 8 Bar, Coupled with 60Hz ODP Electric Motor and Gear Drive. Pressure Gauge, Air Release Valve and Casing Relief Valve are included. | F5: =H5/3.675 -> 25420.585 | H5: 93420.651
A6: LIFECO-UK | B6: 126064200559 | C6: 088001200094 | D6: LIFECO-UK-UL Listed Vertical Turbine Pump (LFP 200-30 VT-2900RPM) 200 GPM @ 9 to 11 Bar, Coupled with 60Hz ODP Electric Motor and Gear Drive. Pressure Gauge, Air Release Valve and Casing Relief Valve are included. | F6: =H6/3.675 -> 26263.155 | H6: 96517.096
A7: LIFECO-UK | B7: 126064200560 | C7: 088001200061 | D7: LIFECO-UK-UL Listed Vertical Turbine Pump (LFP 200-30 VT-2900RPM) 200 GPM @ 12 to 13 Bar, Coupled with 60Hz ODP Electric Motor and Gear Drive. Pressure Gauge, Air Release Valve and Casing Relief Valve are included. | F7: =H7/3.675 -> 28656.543 | H7: 105312.8
A8: LIFECO-UK | B8: 126064200561 | C8: 088001200061 | D8: LIFECO-UK-UL Listed Vertical Turbine Pump (LFP 200-30 VT-2900RPM) 200 GPM @ 14 Bar, Coupled with 60Hz ODP Electric Motor and Gear Drive. Pressure Gauge, Air Release Valve and Casing Relief Valve are included. | F8: =H8/3.675 -> 28656.543 | H8: 105312.8
A9: LIFECO-UK | B9: 126064200562 | C9: 088001200020 | D9: LIFECO-UK-UL Listed Vertical Turbine Pump (LFP 200-30 VT-2900RPM) 200 GPM @ 15 Bar, Coupled with 60Hz ODP Electric Motor and Gear Drive. Pressure Gauge, Air Release Valve and Casing Relief Valve are included. | F9: =H9/3.675 -> 29770.048 | H9: 109404.93
A10: LIFECO-UK | B10: 126064200563 | C10: 088001200020 | D10: LIFECO-UK-UL Listed Vertical Turbine Pump (LFP 200-30 VT-2900RPM) 200 GPM @ 16 Bar, Coupled with 60Hz ODP Electric Motor and Gear Drive. Pressure Gauge, Air Release Valve and Casing Relief Valve are included. | F10: =H10/3.675 -> 30761.442 | H10: 113048.3
A11: LIFECO-UK | B11: 126064200564 | C11: 088001200020 | D11: LIFECO-UK-UL Listed Vertical Turbine Pump (LFP 200-30 VT-2900RPM) 200 GPM @ 17 Bar, Coupled with 60Hz ODP Electric Motor and Gear Drive. Pressure Gauge, Air Release Valve and Casing Relief Valve are included. | F11: =H11/3.675 -> 30761.442 | H11: 113048.3
A12: LIFECO-UK | B12: 126064200565 | C12: 088001200020 | D12: LIFECO-UK-UL Listed Vertical Turbine Pump (LFP 200-30 VT-2900RPM) 200 GPM @ 18 Bar, Coupled with 60Hz ODP Electric Motor and Gear Drive. Pressure Gauge, Air Release Valve and Casing Relief Valve are included. | F12: =H12/3.675 -> 30761.442 | H12: 113048.3
A13: LIFECO-UK | B13: 126064200566 | C13: 088001200057 | D13: LIFECO-UK-UL Listed Vertical Turbine Pump (LFP 200-30 VT-2980RPM) 200 GPM @ 19 Bar, Coupled with 60Hz ODP Electric Motor and Gear Drive. Pressure Gauge, Air Release Valve and Casing Relief Valve are included. | F13: =H13/3.675 -> 33723.412 | H13: 123933.54
A14: LIFECO-UK | B14: 126064200567 | C14: 088001200057 | D14: LIFECO-UK-UL Listed Vertical Turbine Pump (LFP 200-30 VT-2900RPM) 200 GPM @ 20 Bar, Coupled with 60Hz ODP Electric Motor and Gear Drive. Pressure Gauge, Air Release Valve and Casing Relief Valve are included. | F14: =H14/3.675 -> 35311.626 | H14: 129770.23
... A77: LIFECO-UK | B77: 126064200630 | C77: 088001200020 | D77: LIFECO-UK-UL Listed Vertical Turbine Pump (LFP 750-30 VT-2950RPM) 750 GPM @ 11 Bar, Coupled with 60Hz ODP Electric Motor and Gear Drive. Pressure Gauge, Air Release Valve and Casing Relief Valve are included. | F77: =H77/3.675 -> 29770.048 | H77: 109404.93
A78: LIFECO-UK | B78: 126064200915 | C78: 088001200020 | D78: LIFECO-UK-UL Listed Vertical Turbine Pump (LFP 750-30 VT-3000RPM) 750 GPM @ 11.93 Bar, Coupled with 60Hz ODP Electric Motor and Gear Drive. Pressure Gauge, Air Release Valve and Casing Relief Valve are included. | F78: =H78/3.675 -> 29770.048 | H78: 109404.93
A79: LIFECO-UK | B79: 126064200631 | C79: 088001200020 | D79: LIFECO-UK-UL Listed Vertical Turbine Pump (LFP 750-30 VT-2900RPM) 750 GPM @ 12.41 Bar, Coupled with 60Hz ODP Electric Motor and Gear Drive. Pressure Gauge, Air Release Valve and Casing Relief Valve are included. | F79: =H79/3.675 -> 30761.442 | H79: 113048.3
A80: LIFECO-UK | B80: 126064200632 | C80: 088001200020 | D80: LIFECO-UK-UL Listed Vertical Turbine Pump (LFP 750-30 VT-2900RPM) 750 GPM @ 13 Bar, Coupled with 60Hz ODP Electric Motor and Gear Drive. Pressure Gauge, Air Release Valve and Casing Relief Valve are included. | F80: =H80/3.675 -> 30761.442 | H80: 113048.3
A81: LIFECO-UK | B81: 126064200633 | C81: 088001200020 | D81: LIFECO-UK-UL Listed Vertical Turbine Pump (LFP 750-30 VT-2950RPM) 750 GPM @ 14 Bar, Coupled with 60Hz ODP Electric Motor and Gear Drive. Pressure Gauge, Air Release Valve and Casing Relief Valve are included. | F81: =H81/3.675 -> 30761.442 | H81: 113048.3
A82: LIFECO-UK | B82: 126064200634 | C82: 088001200020 | D82: LIFECO-UK-UL Listed Vertical Turbine Pump (LFP 750-30 VT-2900RPM) 750 GPM @ 15 Bar, Coupled with 60Hz ODP Electric Motor and Gear Drive. Pressure Gauge, Air Release Valve and Casing Relief Valve are included. | F82: =H82/3.675 -> 32721.333 | H82: 120250.9
A83: LIFECO-UK | B83: 126064200635 | C83: 088001200020 | D83: LIFECO-UK-UL Listed Vertical Turbine Pump (LFP 750-30 VT-2900RPM) 750 GPM @ 16 Bar, Coupled with 60Hz ODP Electric Motor and Gear Drive. Pressure Gauge, Air Release Valve and Casing Relief Valve are included. | F83: =H83/3.675 -> 32721.333 | H83: 120250.9
A84: LIFECO-UK | B84: 126064200636 | C84: 088001200076 | D84: LIFECO-UK-UL Listed Vertical Turbine Pump (LFP 750-30 VT-2950RPM) 750 GPM @ 17 Bar, Coupled with 60Hz ODP Electric Motor and Gear Drive. Pressure Gauge, Air Release Valve and Casing Relief Valve are included. | F84: =H84/3.675 -> 40576.163 | H84: 149117.4

Sheet Column Pipe VTP
A1: Column Pipe VTP
A2: Item of | B2: Item Code | C2: Item Code | D2: Description | F2: LIFECO-UK GP (USD) | H2: LIFECO-UK GP (AED)
A3: LIFECO-UK | B3: SF-PMPUL30VTCP01 | C3: 106049200055 | D3: 500 mm Additional Column pipe for 30-VT pump | F3: 1246.4375 | H3: 4580.6578
A4: LIFECO-UK | B4: SF-PMPUL30VTCP02 | C4: 106049200056 | D4: 1000 mm Additional Column pipe for 30-VT pump | F4: 1590.05 | H4: 5843.4337
A5: LIFECO-UK | B5: SF-PMPUL30VTCP03 | C5: 106049200058 | D5: 2000 mm Additional Column pipe for 30-VT pump | F5: 1953.875 | H5: 7180.4906
A6: LIFECO-UK | B6: SF-PMPUL30VTCP04 | C6: 106049200061 | D6: 3000 mm Additional Column pipe for 30-VT pump | F6: 2182.95 | H6: 8022.3413

Sheet LF Stand. Pump
A1: LIFECO-UK Costum Engineered Fire Pump - Gmax
A2: Item of | B2: Item Code | C2: Item Code | D2: Description | F2: LIFECO-UK GP (USD) | H2: LIFECO-UK GP (AED)
D3: 100 GPM Models
A4: LIFECO-UK | B4: LF-PMPSTDHES001 | C4: 047017200163 | D4: Pump Set, Electrical Motor and Diesel Engine Driven, Horizontal End Suction Type, Capacity 100 GPM at 6 Bar with Jockey Pump, Controller DOL and Standard Accessories Excel Series, Standard Approved, LIFECO-UK, Model 100 EDJ-6 | F4: =H4/3.675 -> 9755.1916 | H4: 35850.329
A5: LIFECO-UK | B5: LF-PMPSTDHES002 | C5: 047017200214 | D5: Pump Set, Electrical Motor and Diesel Engine Driven, Horizontal End Suction Type, Capacity 100 GPM at 7 Bar with Jockey Pump, Controller DOL and Standard Accessories Excel Series, Standard Approved, LIFECO-UK, Model 100 EDJ-7 | F5: =H5/3.675 -> 9755.1916 | H5: 35850.329
A6: LIFECO-UK | B6: LF-PMPSTDHES003 | C6: 235022200002 | D6: Pump Set, Electrical Motor and Diesel Engine Driven, Horizontal End Suction Type, Capacity 100 GPM at 7 Bar with Pressure Tank, Controller DOL and Standard Accessories, Excel Series, Standard Approved, LIFECO-UK, Model 100 EDPT-7 DOL | F6: =H6/3.675 -> 8891.2519 | H6: 32675.351
A7: LIFECO-UK | B7: LF-PMPSTDHES004 | C7: 047017200168 | D7: Pump Set, Electrical Motor and Diesel Engine Driven, Horizontal End Suction Type, Capacity 100 GPM at 8 Bar with Jockey Pump, Controller DOL and Standard Accessories Excel Series, Standard Approved, LIFECO-UK, Model 100 EDJ-8 | F7: =H7/3.675 -> 9494.178 | H7: 34891.104
A8: LIFECO-UK | B8: LF-PMPSTDHES005 | C8: 047017900041 | D8: LIFECO-UK Fire Pump Set, Electrical Motor and Diesel Engine Driven, Horizontal End Suction Type, Capacity 100 GPM @ 9 Bar with Jockey Pump, Common Controller DOL Starter and Standard Accessories, Excel Series, Standard Approved, LIFECO-UK,Model 100 EDJ-9 | F8: =H8/3.675 -> 9494.178 | H8: 34891.104
D9: 120 GPM Models
A10: LIFECO-UK | B10: LF-PMPSTDHES006 | C10: 235003200026 | D10: LIFECO-UK Fire Pump Set, Electrical Motor and Diesel Engine Driven, Horizontal End Suction Type, Capacity 120 GPM @ 6 Bar with Jockey Pump, Common Controller DOL Starter and Standard Accessories, Excel Series, Standard Approved, LIFECO-UK,Model 120 EDJ-6 | F10: =H10/3.675 -> 9681.1614 | H10: 35578.268
A11: LIFECO-UK | B11: LF-PMPSTDHES007 | C11: 047017200016 | D11: LIFECO-UK Fire Pump Set, Electrical Motor and Diesel Engine Driven, Horizontal End Suction Type, Capacity 120 GPM @ 7 Bar with Jockey Pump, Common Controller DOL Starter and Standard Accessories, Excel Series, Standard Approved, LIFECO-UK,Model 120 EDJ-7 | F11: =H11/3.675 -> 9681.1614 | H11: 35578.268
A12: LIFECO-UK | B12: LF-PMPSTDHES008 | C12: 047017200226 | D12: LIFECO-UK Fire Pump Set, Electrical Motor and Diesel Engine Driven, Horizontal End Suction Type, Capacity 120 GPM @ 8 Bar with Jockey Pump, Common Controller DOL Starter and Standard Accessories, Excel Series, Standard Approved, LIFECO-UK,Model 120 EDJ-8 | F12: =H12/3.675 -> 10135.264 | H12: 37247.095
A13: LIFECO-UK | B13: LF-PMPSTDHES009 | C13: 235003200027 | D13: LIFECO-UK Fire Pump Set, Electrical Motor and Diesel Engine Driven, Horizontal End Suction Type, Capacity 120 GPM @ 9 Bar with Jockey Pump, Common Controller DOL Starter and Standard Accessories, Excel Series, Standard Approved, LIFECO-UK,Model 120 EDJ-9 | F13: =H13/3.675 -> 10135.264 | H13: 37247.095
D14: 150 GPM Models
A15: LIFECO-UK | B15: LF-PMPSTDHES010 | C15: 047002200005 | D15: LIFECO-UK Pump Set, Electrical Motor and Diesel Engine Driven, Horizontal End Suction Type, Capacity 150 GPM at 6 Bar with Jockey Pump and Pressure Tank, Controller DOL and Standard Accessories Excel Series, Standard Approved, LIFECO-UK, Model 150 EDJPT-6 | F15: =H15/3.675 -> 9925.3846 | H15: 36475.788
A16: LIFECO-UK | B16: LF-PMPSTDHES011 | C16: 047013200007 | D16: LIFECO-UK Fire Pump Set, Electrical Motor and Diesel Engine Driven, Horizontal End Suction Type, Capacity 150 GPM @ 7 Bar with Jockey Pump, Common Controller DOL Starter and Standard Accessories, Excel Series, Standard Approved, LIFECO-UK,Model 150 EDJ-7 | F16: =H16/3.675 -> 10047.496 | H16: 36924.549
A17: LIFECO-UK | B17: LF-PMPSTDHES012 | C17: 090008200002 | D17: LIFECO-UK Fire Pump Set, Electrical Motor and Diesel Engine Driven, Horizontal End Suction Type, Capacity 150 GPM @ 8 Bar with Jockey Pump, Common Controller DOL Starter and Standard Accessories, Excel Series, Standard Approved, LIFECO-UK,Model 150 EDJ-8 | F17: =H17/3.675 -> 10112.368 | H17: 37162.952
A18: LIFECO-UK | B18: LF-PMPSTDHES013 | C18: 235003200066 | D18: LIFECO-UK Fire Pump Set, Electrical Motor and Diesel Engine Driven, Horizontal End Suction Type, Capacity 150 GPM @ 9 Bar with Jockey Pump, Common Controller DOL Starter and Standard Accessories, Excel Series, Standard Approved, LIFECO-UK,Model 150 EDJ-9 | F18: =H18/3.675 -> 10356.591 | H18: 38060.473
D19: 200 GPM Models
A20: LIFECO-UK | B20: LF-PMPSTDHES014 | C20: 235003200067 | D20: LIFECO-UK Fire Pump Set, Electrical Motor and Diesel Engine Driven, Horizontal End Suction Type, Capacity 200 GPM @ 6 Bar with Jockey Pump, Common Controller DOL Starter and Standard Accessories, Excel Series, Standard Approved, LIFECO-UK,Model 200 EDJ-6 | F20: =H20/3.675 -> 11356.38 | H20: 41734.697
A21: LIFECO-UK | B21: LF-PMPSTDHES015 | C21: 126064200070 | D21: LIFECO-UK Fire Pump Set, Electrical Motor and Diesel Engine Driven, Horizontal End Suction Type, Capacity 200 GPM @ 7 Bar with Jockey Pump, Common Controller DOL Starter and Standard Accessories, Excel Series, Standard Approved, LIFECO-UK,Model 200 EDJ-7 | F21: =H21/3.675 -> 11470.86 | H21: 42155.41
A22: LIFECO-UK | B22: LF-PMPSTDHES016 | C22: 126064200071 | D22: LIFECO-UK Fire Pump Set, Electrical Motor and Diesel Engine Driven, Horizontal End Suction Type, Capacity 200 GPM @ 8 Bar with Jockey Pump, Common Controller DOL Starter and Standard Accessories, Excel Series, Standard Approved, LIFECO-UK,Model 200 EDJ-8 | F22: =H22/3.675 -> 11524.284 | H22: 42351.742
A23: LIFECO-UK | B23: LF-PMPSTDHES017 | C23: 102002200040 | D23: LIFECO-UK Fire Pump Set, Electrical Motor and Diesel Engine Driven, Horizontal End Suction Type, Capacity 200 GPM @ 9 Bar with Jockey Pump, Common Controller DOL Starter and Standard Accessories, Excel Series, Standard Approved, LIFECO-UK,Model 200 EDJ-9 | F23: =H23/3.675 -> 11997.466 | H23: 44090.688
A24: LIFECO-UK | B24: LF-PMPSTDHES018 | C24: 235003200028 | D24: LIFECO-UK Fire Pump Set, Electrical Motor and Diesel Engine Driven, Horizontal End Suction Type, Capacity 200 GPM @ 10 Bar with Jockey Pump, Common Controller DOL Starter and Standard Accessories, Excel Series, Standard Approved, LIFECO-UK,Model 200 EDJ-10 | F24: =H24/3.675 -> 13008.703 | H24: 47806.983
D25: 250 GPM Models
A26: LIFECO-UK | B26: LF-PMPSTDHES019 | C26: 047017200020 | D26: LIFECO-UK Fire Pump Set, Electrical Motor and Diesel Engine Driven, Horizontal End Suction Type, Capacity 250 GPM at 5 Bar with Jockey Pump, Controller DOL and Standard Accessories Excel Series, Standard Approved, LIFECO-UK,Model 250 EDJ-5 | F26: =H26/3.675 -> 11646.395 | H26: 42800.502
A27: LIFECO-UK | B27: LF-PMPSTDHES020 | C27: 047017200018 | D27: LIFECO-UK Fire Pump Set, Electrical Motor and Diesel Engine Driven, Horizontal End Suction Type, Capacity 250 GPM at 6 Bar with Jockey Pump, Controller DOL and Standard Accessories Excel Series, Standard Approved, LIFECO-UK,Model 250 EDJ-6 | F27: =H27/3.675 -> 11364.012 | H27: 41762.744
A28: LIFECO-UK | B28: LF-PMPSTDHES021 | C28: 047017200171 | D28: LIFECO-UK Fire Pump Set, Electrical Motor and Diesel Engine Driven, Horizontal End Suction Type, Capacity 250 GPM at 7 Bar with Jockey Pump, Controller DOL and Standard Accessories Excel Series, Standard Approved, LIFECO-UK,Model 250 EDJ-7 | F28: =H28/3.675 -> 11524.284 | H28: 42351.742
A29: LIFECO-UK | B29: LF-PMPSTDHES022 | C29: 235018200005 | D29: LIFECO-UK Fire Pump Set, Electrical Motor and Diesel Engine Driven, Horizontal End Suction Type, Capacity 250 GPM at 7 Bar with Jockey Pump and 24 Litre Pressure Tank, Controller DOL and Standard Accessories Excel Series, Standard Approved, LIFECO-UK,Model 250 EDJPT-7 | F29: =H29/3.675 -> 11600.603 | H29: 42632.217
B30: LF-PMPSTDHES023 | C30: 047017200019 | D30: LIFECO-UK Fire Pump Set, Electrical Motor and Diesel Engine Driven, Horizontal End Suction Type, Capacity 250 GPM @ 8 Bar with Jockey Pump, Common Controller DOL Starter and Standard Accessories, Excel Series, Standard Approved, LIFECO-UK,Model 250 EDJ-8 | F30: =H30/3.675 -> 12058.522 | H30: 44315.068
A31: LIFECO-UK | B31: LF-PMPSTDHES024 | C31: 047017200141 | D31: LIFECO-UK Fire Pump Set, Electrical Motor and Diesel Engine Driven, Horizontal End Suction Type, Capacity 250 GPM @ 9 Bar with Jockey Pump, Common Controller DOL Starter and Standard Accessories, Excel Series, Standard Approved, LIFECO-UK,Model 250 EDJ-9 | F31: =H31/3.675 -> 12073.786 | H31: 44371.163
A32: LIFECO-UK | B32: LF-PMPSTDHES025 | C32: 047017200110 | D32: LIFECO-UK Fire Pump Set, Electrical Motor and Diesel Engine Driven, Horizontal End Suction Type, Capacity 250 GPM @ 10 Bar with Jockey Pump, Common Controller DOL Starter and Standard Accessories, Excel Series, Standard Approved, LIFECO-UK,Model 250 EDJ-10 | F32: =H32/3.675 -> 13920.724 | H32: 51158.661
D33: 300 GPM Models
A34: LIFECO-UK | B34: LF-PMPSTDHES026 | C34: 102002200048 | D34: LIFECO-UK Fire Pump Set, Electrical Motor and Diesel Engine Driven, Horizontal End Suction Type, Capacity 300 GPM @ 6 Bar with Jockey Pump, Common Controller DOL Starter and Standard Accessories, Excel Series, Standard Approved, LIFECO-UK,Model 300 EDJ-6 | F34: =H34/3.675 -> 12173.002 | H34: 44735.781
A35: LIFECO-UK | B35: LF-PMPSTDHES027 | C35: 047017200174 | D35: LIFECO-UK Fire Pump Set, Electrical Motor and Diesel Engine Driven, Horizontal End Suction Type, Capacity 300 GPM @ 7 Bar with Jockey Pump, Common Controller DOL Starter and Standard Accessories, Excel Series, Standard Approved, LIFECO-UK,Model 300 EDJ-7 | F35: =H35/3.675 -> 12180.633 | H35: 44763.828
A36: LIFECO-UK | B36: LF-PMPSTDHES028 | C36: 047017200115 | D36: LIFECO-UK Fire Pump Set, Electrical Motor and Diesel Engine Driven, Horizontal End Suction Type, Capacity 300 GPM @ 8 Bar with Jockey Pump, Common Controller DOL Starter and Standard Accessories, Excel Series, Standard Approved, LIFECO-UK,Model 300 EDJ-8 | F36: =H36/3.675 -> 12993.439 | H36: 47750.888
A37: LIFECO-UK | B37: LF-PMPSTDHES029 | C37: 090008200004 | D37: LIFECO-UK Fire Pump Set, Electrical Motor and Diesel Engine Driven, Horizontal End Suction Type, Capacity 300 GPM @ 9 Bar with Jockey Pump, Common Controller DOL Starter and Standard Accessories, Excel Series, Standard Approved, LIFECO-UK,Model 300 EDJ-9 | F37: =H37/3.675 -> 12993.439 | H37: 47750.888
A38: LIFECO-UK | B38: LF-PMPSTDHES030 | C38: 102002200072 | D38: LIFECO-UK Fire Pump Set, Electrical Motor and Diesel Engine Driven, Horizontal End Suction Type, Capacity 300 GPM @ 10 Bar with Jockey Pump, Common Controller DOL Starter and Standard Accessories, Excel Series, Standard Approved, LIFECO-UK,Model 300 EDJ-10 | F38: =H38/3.675 -> 15569.231 | H38: 57216.923
D39: 350 GPM Models
A40: LIFECO-UK | B40: LF-PMPSTDHES031 | C40: 235003200029 | D40: LIFECO-UK Fire Pump Set, Electrical Motor and Diesel Engine Driven, Horizontal End Suction Type, Capacity 350 GPM @ 6 Bar with Jockey Pump, Common Controller DOL Starter and Standard Accessories, Excel Series, Standard Approved, LIFECO-UK,Model 350 EDJ-6 | F40: =H40/3.675 -> 12219.557 | H40: 44906.87
...

Sheet UL Electric Split Case 50Hz
A1: UL Electric Split Case 50Hz
A2: Item of | B2: LIFECO-UK Item Code | C2: Supplier Item Code | D2: Description | F2: LIFECO-UK GP (USD) | H2: LIFECO-UK GP (AED)
A3: LIFECO-UK | C3: 231007200579 | D3: LIFECO-UK-UL Listed Split Case (GMS 150-28SM) Electric Motor Driven Skid Pump 150 GPM @ 6.96 Bar Coupled with UL Listed ODP Motor 2900 RPM. Suction and Discharge Pressure Gauges, Air Release Valve and Casing Relief Valve are included. | F3: 10906.571 | H3: =F3*3.675 -> 40081.647
A4: LIFECO-UK | C4: 231007200580 | D4: LIFECO-UK-UL Listed Split Case (GMS 150-28SM) Electric Motor Driven Skid Pump 150 GPM @ 8 Bar Coupled with UL Listed ODP Motor. Suction and Discharge Pressure Gauges, Air Release Valve and Casing Relief Valve are included. | F4: 11636.378 | H4: =F4*3.675 -> 42763.69
A5: LIFECO-UK | C5: 231007200581 | D5: LIFECO-UK-UL Listed Split Case (GMS 150-28SM) Electric Motor Driven Skid Pump 150 GPM @ 9 Bar Coupled with UL Listed ODP Motor. Suction and Discharge Pressure Gauges, Air Release Valve and Casing Relief Valve are included. | F5: 11636.378 | H5: =F5*3.675 -> 42763.69
A6: LIFECO-UK | C6: 231007200582 | D6: LIFECO-UK-UL Listed Split Case (GMS 150-28SM) Electric Motor Driven Skid Pump 150 GPM @ 10 Bar Coupled with UL Listed ODP Motor. Suction and Discharge Pressure Gauges, Air Release Valve and Casing Relief Valve are included. | F6: 12851.363 | H6: =F6*3.675 -> 47228.761
A7: LIFECO-UK | C7: 231007200583 | D7: LIFECO-UK-UL Listed Split Case (GMS 150-28SM) Electric Motor Driven Skid Pump 150 GPM @ 11 Bar Coupled with UL Listed ODP Motor. Suction and Discharge Pressure Gauges, Air Release Valve and Casing Relief Valve are included. | F7: 13594.696 | H7: =F7*3.675 -> 49960.506
A8: LIFECO-UK | C8: 231007200584 | D8: LIFECO-UK-UL Listed Split Case (GMS 150-35SM) Electric Motor Driven Skid Pump 150 GPM @ 12 Bar Coupled with UL Listed ODP Motor. Suction and Discharge Pressure Gauges, Air Release Valve and Casing Relief Valve are included. | F8: 15082.692 | H8: =F8*3.675 -> 55428.894
A9: LIFECO-UK | C9: 231007200585 | D9: LIFECO-UK-UL Listed Split Case (GMS 150-35SM) Electric Motor Driven Skid Pump 150 GPM @ 13 Bar Coupled with UL Listed ODP Motor. Suction and Discharge Pressure Gauges, Air Release Valve and Casing Relief Valve are included. | F9: 16055.769 | H9: =F9*3.675 -> 59004.952
A10: LIFECO-UK | C10: 231007200586 | D10: LIFECO-UK-UL Listed Split Case (GMS 150-35SM) Electric Motor Driven Skid Pump 150 GPM @ 14 Bar Coupled with UL Listed ODP Motor. Suction and Discharge Pressure Gauges, Air Release Valve and Casing Relief Valve are included. | F10: 16217.949 | H10: =F10*3.675 -> 59600.962
A11: LIFECO-UK | C11: 231007200587 | D11: LIFECO-UK-UL Listed Split Case (GMS 150-40SM) Electric Motor Driven Skid Pump 150 GPM @ 15 Bar Coupled with UL Listed ODP Motor. Suction and Discharge Pressure Gauges, Air Release Valve and Casing Relief Valve are included. | F11: 24245.833 | H11: =F11*3.675 -> 89103.437
A12: LIFECO-UK | C12: 231007200588 | D12: LIFECO-UK-UL Listed Split Case (GMS 150-40SM) Electric Motor Driven Skid Pump 150 GPM @ 16 Bar Coupled with UL Listed ODP Motor. Suction and Discharge Pressure Gauges, Air Release Valve and Casing Relief Valve are included. | F12: 24245.833 | H12: =F12*3.675 -> 89103.437
A13: LIFECO-UK | C13: 231007200589 | D13: LIFECO-UK-UL Listed Split Case (GMS 150-40SM) Electric Motor Driven Skid Pump 150 GPM @ 17 Bar Coupled with UL Listed ODP Motor. Suction and Discharge Pressure Gauges, Air Release Valve and Casing Relief Valve are included. | F13: 28057.051 | H13: =F13*3.675 -> 103109.66
A14: LIFECO-UK | C14: 231007200590 | D14: LIFECO-UK-UL Listed Split Case (GMS 150-40SM) Electric Motor Driven Skid Pump 150 GPM @ 18 Bar Coupled with UL Listed ODP Motor. Suction and Discharge Pressure Gauges, Air Release Valve and Casing Relief Valve are included. | F14: 28057.051 | H14: =F14*3.675 -> 103109.66
... A199: LIFECO-UK | C199: 231007200771 | D199: LIFECO-UK-UL Listed Split Case (GMS 3500-61SL5-2G) Electric Motor Driven Skid Pump 3500 GPM @ 10.2 Bar Coupled with UL Listed ODP Motor. Suction and Discharge Pressure Gauges, Air Release Valve and Casing Relief Valve are included. | F199: 81657.372 | H199: =F199*3.675 -> 300090.84

Sheet UL Diesel Split case
A1: UL Diesel Split case
A2: Item of | B2: LIFECO-UK Item Code | C2: Supplier Item Code | D2: Description | F2: LIFECO-UK GP (USD) | H2: LIFECO-UK GP (AED)
A3: LIFECO-UK | C3: 231007200772 | D3: LIFECO-UK-UL Listed Split Case (GMS 150-28SM) Engine Driven Skid Pump 150 GPM @ 6.96 Bar Coupled with UL Listed Stallion Engine. Suction and Discharge Pressure Gauges and Air Release Valve are included. | F3: 20126.474 | H3: =F3*3.675 -> 73964.793
A4: LIFECO-UK | C4: 231007200773 | D4: LIFECO-UK-UL Listed Split Case (GMS 150-28SM) Engine Driven Skid Pump 150 GPM @ 8 Bar Coupled with UL Listed Stallion Engine. Suction and Discharge Pressure Gauges and Air Release Valve are included. | F4: 20778.186 | H4: =F4*3.675 -> 76359.832
A5: LIFECO-UK | C5: 231007200774 | D5: LIFECO-UK-UL Listed Split Case (GMS 150-28SM) Engine Driven Skid Pump 150 GPM @ 9 Bar Coupled with UL Listed Stallion Engine. Suction and Discharge Pressure Gauges and Air Release Valve are included. | F5: 20853.853 | H5: =F5*3.675 -> 76637.909
A6: LIFECO-UK | C6: 231007200775 | D6: LIFECO-UK-UL Listed Split Case (GMS 150-28SM) Engine Driven Skid Pump 150 GPM @ 10 Bar Coupled with UL Listed Stallion Engine. Suction and Discharge Pressure Gauges and Air Release Valve are included. | F6: 20929.52 | H6: =F6*3.675 -> 76915.987
A7: LIFECO-UK | C7: 126064200078 | D7: LIFECO-UK-UL Listed Split Case (GMS 150-28SM) Engine Driven Skid Pump 150 GPM @ 11 Bar Coupled with FM Listed Stallion Engine. Suction and Discharge Pressure Gauges and Air Release Valve are included. | F7: 21232.189 | H7: =F7*3.675 -> 78028.296
A8: LIFECO-UK | C8: 231007200777 | D8: LIFECO-UK-UL Listed Split Case (GMS 150-35SM) Engine Driven Skid Pump 150 GPM @ 12 Bar Coupled with UL Listed Stallion Engine. Suction and Discharge Pressure Gauges and Air Release Valve are included. | F8: 22442.866 | H8: =F8*3.675 -> 82477.534
A9: LIFECO-UK | C9: 231007200778 | D9: LIFECO-UK-UL Listed Split Case (GMS 150-35SM) Engine Driven Skid Pump 150 GPM @ 13 Bar Coupled with UL Listed Stallion Engine. Suction and Discharge Pressure Gauges and Air Release Valve are included. | F9: 29840.532 | H9: =F9*3.675 -> 109663.96
A10: LIFECO-UK | C10: 231007200779 | D10: LIFECO-UK-UL Listed Split Case (GMS 150-35SM) Engine Driven Skid Pump 150 GPM @ 14 Bar Coupled with UL Listed Stallion Engine. Suction and Discharge Pressure Gauges and Air Release Valve are included. | F10: 30143.201 | H10: =F10*3.675 -> 110776.26
A11: LIFECO-UK | C11: 231007200780 | D11: LIFECO-UK-UL Listed Split Case (GMS 150-40SM) Engine Driven Skid Pump 150 GPM @ 15 Bar Coupled with UL Listed Stallion Engine. Suction and Discharge Pressure Gauges and Air Release Valve are included. | F11: 40707.051 | H11: =F11*3.675 -> 149598.41
A12: LIFECO-UK | C12: 231007200781 | D12: LIFECO-UK-UL Listed Split Case (GMS 150-40SM) Engine Driven Skid Pump 150 GPM @ 16 Bar Coupled with UL Listed Stallion Engine. Suction and Discharge Pressure Gauges and Air Release Valve are included. | F12: 40707.051 | H12: =F12*3.675 -> 149598.41
A13: LIFECO-UK | C13: 231007200782 | D13: LIFECO-UK-UL Listed Split Case (GMS 150-40SM) Engine Driven Skid Pump 150 GPM @ 17 Bar Coupled with UL Listed Stallion Engine. Suction and Discharge Pressure Gauges and Air Release Valve are included. | F13: 40707.051 | H13: =F13*3.675 -> 149598.41
A14: LIFECO-UK | C14: 231007200783 | D14: LIFECO-UK-UL Listed Split Case (GMS 150-40SM) Engine Driven Skid Pump 150 GPM @ 18 Bar Coupled with UL Listed Stallion Engine. Suction and Discharge Pressure Gauges and Air Release Valve are included. | F14: 42085.577 | H14: =F14*3.675 -> 154664.5
... A197: LIFECO-UK | C197: 231004200119 | D197: LIFECO-UK-UL Listed Split Case (GMS 3500-61SL6-2G) Engine Driven Skid Pump 3500 GPM @ 10.76 Bar Coupled with UL Listed Stallion Engine. Suction and Discharge Pressure Gauges and Air Release Valve are included. | F197: 78900.321 | H197: =F197*3.675 -> 289958.68

Sheet UL Electric Split Case 60Hz
A1: UL Electric Split Case 60Hz
A2: Item of | B2: LIFECO-UK Item Code | C2: Supplier Item Code | D2: Description | F2: LIFECO-UK GP (USD) | H2: LIFECO-UK GP (AED)
A3: LIFECO-UK | C3: 231007201254 | D3: LIFECO-UK-UL Listed Split Case (GMS 150-25SH) Electric Motor Driven Skid Pump 150 GPM @ 7.86 Bar Coupled with UL Listed ODP Motor. Suction and Discharge Pressure Gauges, Air Release Valve and Casing Relief Valve are included. | F3: 12851.363 | H3: =F3*3.675 -> 47228.761
A4: LIFECO-UK | C4: 231007201255 | D4: LIFECO-UK-UL Listed Split Case (GMS 150-25SH) Electric Motor Driven Skid Pump 150 GPM @ 8 Bar Coupled with UL Listed ODP Motor. Suction and Discharge Pressure Gauges, Air Release Valve and Casing Relief Valve are included. | F4: 12851.363 | H4: =F4*3.675 -> 47228.761
A5: LIFECO-UK | C5: 231007201256 | D5: LIFECO-UK-UL Listed Split Case (GMS 150-25SH) Electric Motor Driven Skid Pump 150 GPM @ 9 Bar Coupled with UL Listed ODP Motor. Suction and Discharge Pressure Gauges, Air Release Valve and Casing Relief Valve are included. | F5: 13683.704 | H5: =F5*3.675 -> 50287.612
A6: LIFECO-UK | C6: 231007201257 | D6: LIFECO-UK-UL Listed Split Case (GMS 150-25SH) Electric Motor Driven Skid Pump 150 GPM @ 10 Bar Coupled with UL Listed ODP Motor. Suction and Discharge Pressure Gauges, Air Release Valve and Casing Relief Valve are included. | F6: 13683.704 | H6: =F6*3.675 -> 50287.612
A7: LIFECO-UK | C7: 231007201258 | D7: LIFECO-UK-UL Listed Split Case (GMS 150-25SH) Electric Motor Driven Skid Pump 150 GPM @ 11 Bar Coupled with UL Listed ODP Motor. Suction and Discharge Pressure Gauges, Air Release Valve and Casing Relief Valve are included. | F7: 15491.117 | H7: =F7*3.675 -> 56929.854
A8: LIFECO-UK | C8: 231007201259 | D8: LIFECO-UK-UL Listed Split Case (GMS 150-25SH) Electric Motor Driven Skid Pump 150 GPM @ 12 Bar Coupled with UL Listed ODP Motor. Suction and Discharge Pressure Gauges, Air Release Valve and Casing Relief Valve are included. | F8: 15491.117 | H8: =F8*3.675 -> 56929.854
A9: LIFECO-UK | C9: 231007201260 | D9: LIFECO-UK-UL Listed Split Case (GMS 150-25SH) Electric Motor Driven Skid Pump 150 GPM @ 13 Bar Coupled with UL Listed ODP Motor. Suction and Discharge Pressure Gauges, Air Release Valve and Casing Relief Valve are included. | F9: 15491.117 | H9: =F9*3.675 -> 56929.854
A10: LIFECO-UK | C10: 231007201261 | D10: LIFECO-UK-UL Listed Split Case (GMS 150-25SH) Electric Motor Driven Skid Pump 150 GPM @ 14.34 Bar Coupled with UL Listed ODP Motor. Suction and Discharge Pressure Gauges, Air Release Valve and Casing Relief Valve are included. | F10: 16428.782 | H10: =F10*3.675 -> 60375.774
A11: LIFECO-UK | C11: 231007201262 | D11: LIFECO-UK-UL Listed Split Case (GMS 150-SN31SH) Electric Motor Driven Skid Pump 150 GPM @ 15.58 Bar Coupled with UL Listed ODP Motor. Suction and Discharge Pressure Gauges, Air Release Valve and Casing Relief Valve are included. | F11: 15491.117 | H11: =F11*3.675 -> 56929.854
A12: LIFECO-UK | C12: 231007201263 | D12: LIFECO-UK-UL Listed Split Case (GMS 150-SN31SH) Electric Motor Driven Skid Pump 150 GPM @ 16 Bar Coupled with UL Listed ODP Motor. Suction and Discharge Pressure Gauges, Air Release Valve and Casing Relief Valve are included. | F12: 15491.117 | H12: =F12*3.675 -> 56929.854
A13: LIFECO-UK | C13: 231007201264 | D13: LIFECO-UK-UL Listed Split Case (GMS 150-SN31SH) Electric Motor Driven Skid Pump 150 GPM @ 17 Bar Coupled with UL Listed ODP Motor. Suction and Discharge Pressure Gauges, Air Release Valve and Casing Relief Valve are included. | F13: 16258.494 | H13: =F13*3.675 -> 59749.964
A14: LIFECO-UK | C14: 231007201265 | D14: LIFECO-UK-UL Listed Split Case (GMS 150-SN31SH) Electric Motor Driven Skid Pump 150 GPM @ 18 Bar Coupled with UL Listed ODP Motor. Suction and Discharge Pressure Gauges, Air Release Valve and Casing Relief Valve are included. | F14: 16258.494 | H14: =F14*3.675 -> 59749.964
... A171: LIFECO-UK | C171: 231007201422 | D171: LIFECO-UK-UL Listed Split Case (GMS 3500-61SL6-2G) Electric Motor Driven Skid Pump 3500 GPM @ 10.76 Bar Coupled with UL Listed ODP Motor. Suction and Discharge Pressure Gauges, Air Release Valve and Casing Relief Valve are included. | F171: 81657.372 | H171: =F171*3.675 -> 300090.84

Sheet UL FM Electric Split Case 50Hz
A1: UL/FM Electric Split Case 50Hz
A2: Item of | B2: LIFECO-UK Item Code | C2: Supplier Item Code | D2: Description | F2: LIFECO-UK GP (USD) | H2: LIFECO-UK GP (AED)
A3: LIFECO-UK | C3: 231007200940 | D3: LIFECO-UK-UL/FM Approved Split Case (GMS 150-28SM) Electric Motor Driven Skid Pump 150 GPM @ 6.96 Bar Coupled with UL Listed ODP Motor. Suction and Discharge Pressure Gauges, Air Release Valve and Casing Relief Valve are included. | F3: 11312.019 | H3: =F3*3.675 -> 41571.671
A4: LIFECO-UK | C4: 231007200941 | D4: LIFECO-UK-UL/FM Approved Split Case (GMS 150-28SM) Electric Motor Driven Skid Pump 150 GPM @ 8 Bar Coupled with UL Listed ODP Motor. Suction and Discharge Pressure Gauges, Air Release Valve and Casing Relief Valve are included. | F4: 12082.372 | H4: =F4*3.675 -> 44402.716
A5: LIFECO-UK | C5: 231007200942 | D5: LIFECO-UK-UL/FM Approved Split Case (GMS 150-28SM) Electric Motor Driven Skid Pump 150 GPM @ 9 Bar Coupled with UL Listed ODP Motor. Suction and Discharge Pressure Gauges, Air Release Valve and Casing Relief Valve are included. | F5: 12082.372 | H5: =F5*3.675 -> 44402.716
A6: LIFECO-UK | C6: 231007200943 | D6: LIFECO-UK-UL/FM Approved Split Case (GMS 150-28SM) Electric Motor Driven Skid Pump 150 GPM @ 10 Bar Coupled with UL Listed ODP Motor. Suction and Discharge Pressure Gauges, Air Release Valve and Casing Relief Valve are included. | F6: 13002.698 | H6: =F6*3.675 -> 47784.915
A7: LIFECO-UK | C7: 231007200944 | D7: LIFECO-UK-UL/FM Approved Split Case (GMS 150-28SM) Electric Motor Driven Skid Pump 150 GPM @ 11 Bar Coupled with UL Listed ODP Motor. Suction and Discharge Pressure Gauges, Air Release Valve and Casing Relief Valve are included. | F7: 14000.144 | H7: =F7*3.675 -> 51450.53
A8: LIFECO-UK | C8: 231007200945 | D8: LIFECO-UK-UL/FM Approved Split Case (GMS 150-35SM) Electric Motor Driven Skid Pump 150 GPM @ 12 Bar Coupled with UL Listed ODP Motor. Suction and Discharge Pressure Gauges, Air Release Valve and Casing Relief Valve are included. | F8: 15488.141 | H8: =F8*3.675 -> 56918.918
A9: LIFECO-UK | C9: 231007200946 | D9: LIFECO-UK-UL/FM Approved Split Case (GMS 150-35SM) Electric Motor Driven Skid Pump 150 GPM @ 13 Bar Coupled with UL Listed ODP Motor. Suction and Discharge Pressure Gauges, Air Release Valve and Casing Relief Valve are included. | F9: 16461.218 | H9: =F9*3.675 -> 60494.976
A10: LIFECO-UK | C10: 231007200947 | D10: LIFECO-UK-UL/FM Approved Split Case (GMS 150-35SM) Electric Motor Driven Skid Pump 150 GPM @ 14 Bar Coupled with UL Listed ODP Motor. Suction and Discharge Pressure Gauges, Air Release Valve and Casing Relief Valve are included. | F10: 16745.032 | H10: =F10*3.675 -> 61537.993
A11: LIFECO-UK | C11: 231007200948 | D11: LIFECO-UK-UL/FM Approved Split Case (GMS 150-40SM) Electric Motor Driven Skid Pump 150 GPM @ 15 Bar Coupled with UL Listed ODP Motor. Suction and Discharge Pressure Gauges, Air Release Valve and Casing Relief Valve are included. | F11: 24772.917 | H11: =F11*3.675 -> 91040.469
A12: LIFECO-UK | C12: 231007200949 | D12: LIFECO-UK-UL/FM Approved Split Case (GMS 150-40SM) Electric Motor Driven Skid Pump 150 GPM @ 16 Bar Coupled with UL Listed ODP Motor. Suction and Discharge Pressure Gauges, Air Release Valve and Casing Relief Valve are included. | F12: 24772.917 | H12: =F12*3.675 -> 91040.469
A13: LIFECO-UK | C13: 231007200950 | D13: LIFECO-UK-UL/FM Approved Split Case (GMS 150-40SM) Electric Motor Driven Skid Pump 150 GPM @ 17 Bar Coupled with UL Listed ODP Motor. Suction and Discharge Pressure Gauges, Air Release Valve and Casing Relief Valve are included. | F13: 28584.135 | H13: =F13*3.675 -> 105046.69
A14: LIFECO-UK | C14: 231007200951 | D14: LIFECO-UK-UL/FM Approved Split Case (GMS 150-40SM) Electric Motor Driven Skid Pump 150 GPM @ 18 Bar Coupled with UL Listed ODP Motor. Suction and Discharge Pressure Gauges, Air Release Valve and Casing Relief Valve are included. | F14: 28584.135 | H14: =F14*3.675 -> 105046.69
... A197: LIFECO-UK | C197: 231007201125 | D197: LIFECO-UK-UL/FM Approved Split Case (GMS 3500-61SL5-2G) Electric Motor Driven Skid Pump 3500 GPM @ 10.2 Bar Coupled with UL Listed ODP Motor. Suction and Discharge Pressure Gauges, Air Release Valve and Casing Relief Valve are included. | F197: 82062.821 | H197: =F197*3.675 -> 301580.87

Sheet UL FM Diesel Split Case
A1: UL/FM Diesel Split Case
A2: Item of | B2: LIFECO-UK Item Code | C2: Supplier Item Code | D2: Description | F2: LIFECO-UK GP (USD) | H2: LIFECO-UK GP (AED)
A3: LIFECO-UK | C3: 231007201126 | D3: LIFECO-UK-UL/FM Approved Split Case (GMS 150-28SM) Engine Driven Skid Pump 150 GPM @ 6.96 Bar Coupled with UL/FM Listed Stallion Engine. Suction and Discharge Pressure Gauges and Air Release Valve are included. | F3: 20207.564 | H3: =F3*3.675 -> 74262.798
